---
timestamp: '2025-01-22T14:55:36.516577'
level: INFO
issuer: instance_solver
event_type: metadata
data:
    log_file: /home/remote/u7899572/lifted-white-plan-domain-repair/exp_logs_anu/gbfs-unary-ff
        relax-all lp1/mystery__pprob30-err-rate-0-5.yaml
    instance_id: mystery__pprob30-err-rate-0-5
    search_algorithm: greedy
    plan_length: 10
    domain_class: mystery
    instance_name: pprob30-err-rate-0-5
    ground_plan:
    - (feast triumph turkey chicken surrey pennsylvania)
    - (overcome boils expectation hamburger neptune venus)
    - (feast expectation hamburger beef bosnia bavaria)
    - (feast expectation beef baguette bosnia bavaria)
    - (overcome dread expectation baguette vulcan neptune)
    - (feast expectation baguette cucumber alsace guanabara)
    - (feast expectation cucumber hotdog bosnia bavaria)
    - (feast expectation hotdog mutton moravia kentucky)
    - (succumb boils expectation mutton vulcan neptune)
    - (succumb dread expectation mutton neptune venus)
    lifted_plan:
    -   - feast
        - ?triumph
        - ?turkey
        - ?chicken
        - ?surrey
        - ?pennsylvania
    -   - overcome
        - ?boils
        - ?expectation
        - ?hamburger
        - ?neptune
        - ?venus
    -   - feast
        - ?expectation
        - ?hamburger
        - ?beef
        - ?bosnia
        - ?bavaria
    -   - feast
        - ?expectation
        - ?beef
        - ?baguette
        - ?bosnia
        - ?bavaria
    -   - overcome
        - ?dread
        - ?expectation
        - ?baguette
        - ?vulcan
        - ?neptune
    -   - feast
        - ?expectation
        - ?baguette
        - ?cucumber
        - ?alsace
        - ?guanabara
    -   - feast
        - ?expectation
        - ?cucumber
        - ?hotdog
        - ?bosnia
        - ?bavaria
    -   - feast
        - ?expectation
        - ?hotdog
        - ?mutton
        - ?moravia
        - ?kentucky
    -   - succumb
        - ?boils
        - ?expectation
        - ?mutton
        - ?vulcan
        - ?neptune
    -   - succumb
        - ?dread
        - ?expectation
        - ?mutton
        - ?neptune
        - ?venus


---
timestamp: '2025-01-22T14:55:36.521068'
level: INFO
issuer: instance_solver
event_type: ground_repair
data:
    repair_length: 0
    repair: ''


---
timestamp: '2025-01-22T14:55:46.893567'
level: ERROR
issuer: batch_solver
event_type: error
data:
    error_type: MemoryError
    error_message: Command '['/home/projects/u7899572/conda-envs/main/bin/python3',
        'instance_solver.py', 'greedy', '/home/remote/u7899572/lifted-white-plan-domain-repair/input/benchmarks-G1',
        '/home/remote/u7899572/lifted-white-plan-domain-repair/exp_logs_anu/gbfs-unary-ff
        relax-all lp1/mystery__pprob30-err-rate-0-5.yaml', '1000000', 'mystery__pprob30-err-rate-0-5',
        '1.0', 'unary']' returned non-zero exit status 1.
    stack_trace: "Traceback (most recent call last):\n  File \"batch_solver.py\",\
        \ line 126, in worker\n    result = subprocess.run(cmd, check=True, timeout=params['timeout_seconds'],\n\
        \  File \"/home/projects/u7899572/conda-envs/main/lib/python3.8/subprocess.py\"\
        , line 516, in run\n    raise CalledProcessError(retcode, process.args,\n\
        subprocess.CalledProcessError: Command '['/home/projects/u7899572/conda-envs/main/bin/python3',\
        \ 'instance_solver.py', 'greedy', '/home/remote/u7899572/lifted-white-plan-domain-repair/input/benchmarks-G1',\
        \ '/home/remote/u7899572/lifted-white-plan-domain-repair/exp_logs_anu/gbfs-unary-ff\
        \ relax-all lp1/mystery__pprob30-err-rate-0-5.yaml', '1000000', 'mystery__pprob30-err-rate-0-5',\
        \ '1.0', 'unary']' returned non-zero exit status 1.\n"
    instance_id: mystery__pprob30-err-rate-0-5
    process_info:
        cmd:
        - /home/projects/u7899572/conda-envs/main/bin/python3
        - instance_solver.py
        - greedy
        - /home/remote/u7899572/lifted-white-plan-domain-repair/input/benchmarks-G1
        - /home/remote/u7899572/lifted-white-plan-domain-repair/exp_logs_anu/gbfs-unary-ff
            relax-all lp1/mystery__pprob30-err-rate-0-5.yaml
        - '1000000'
        - mystery__pprob30-err-rate-0-5
        - '1.0'
        - unary
        duration: '11.85'
        python_executable: /home/projects/u7899572/conda-envs/main/bin/python3
    stdout: '[Errno 12] Cannot allocate memory: ''/dev/shm/pddl_files/tmpsdqsw7bl''

        '
    stderr: "Traceback (most recent call last):\n  File \"/home/remote/u7899572/lifted-white-plan-domain-repair/search_partial_grounding/lifted_pddl_grounder.py\"\
        , line 135, in ground_pddl\n  File \"/home/projects/u7899572/conda-envs/main/lib/python3.8/site-packages/lifted_pddl/parser.py\"\
        , line 485, in get_applicable_actions\n  File \"/home/projects/u7899572/conda-envs/main/lib/python3.8/site-packages/lifted_pddl/parser.py\"\
        , line 433, in _get_applicable_var_assigns_action\nMemoryError\n\nDuring handling\
        \ of the above exception, another exception occurred:\n\nTraceback (most recent\
        \ call last):\n  File \"/home/remote/u7899572/lifted-white-plan-domain-repair/search_partial_grounding/node.py\"\
        , line 193, in get_neighbors\n  File \"/home/remote/u7899572/lifted-white-plan-domain-repair/search_partial_grounding/lifted_pddl_grounder.py\"\
        , line 140, in ground_pddl\n  File \"/home/projects/u7899572/conda-envs/main/lib/python3.8/tempfile.py\"\
        , line 836, in __exit__\n  File \"/home/projects/u7899572/conda-envs/main/lib/python3.8/tempfile.py\"\
        , line 840, in cleanup\n  File \"/home/projects/u7899572/conda-envs/main/lib/python3.8/tempfile.py\"\
        , line 822, in _rmtree\n  File \"/home/projects/u7899572/conda-envs/main/lib/python3.8/shutil.py\"\
        , line 718, in rmtree\n  File \"/home/projects/u7899572/conda-envs/main/lib/python3.8/shutil.py\"\
        , line 631, in _rmtree_safe_fd\n  File \"/home/projects/u7899572/conda-envs/main/lib/python3.8/shutil.py\"\
        , line 627, in _rmtree_safe_fd\nOSError: [Errno 12] Cannot allocate memory:\
        \ '/dev/shm/pddl_files/tmpsdqsw7bl'\n\nDuring handling of the above exception,\
        \ another exception occurred:\n\nTraceback (most recent call last):\n  File\
        \ \"instance_solver.py\", line 104, in solve_instance\n  File \"/home/remote/u7899572/lifted-white-plan-domain-repair/search_partial_grounding/search_algorithms.py\"\
        , line 78, in find_path\n  File \"/home/remote/u7899572/lifted-white-plan-domain-repair/search_partial_grounding/node.py\"\
        , line 199, in get_neighbors\n  File \"/home/remote/u7899572/lifted-white-plan-domain-repair/search_partial_grounding/node.py\"\
        , line 234, in to_dict\nMemoryError\n\nDuring handling of the above exception,\
        \ another exception occurred:\n\nTraceback (most recent call last):\n  File\
        \ \"instance_solver.py\", line 136, in <module>\n  File \"instance_solver.py\"\
        , line 106, in solve_instance\n  File \"/home/projects/u7899572/conda-envs/main/lib/python3.8/traceback.py\"\
        , line 167, in format_exc\n  File \"/home/projects/u7899572/conda-envs/main/lib/python3.8/traceback.py\"\
        , line 120, in format_exception\n  File \"/home/projects/u7899572/conda-envs/main/lib/python3.8/traceback.py\"\
        , line 493, in __init__\n  File \"/home/projects/u7899572/conda-envs/main/lib/python3.8/traceback.py\"\
        , line 493, in __init__\n  File \"/home/projects/u7899572/conda-envs/main/lib/python3.8/traceback.py\"\
        , line 508, in __init__\n  File \"/home/projects/u7899572/conda-envs/main/lib/python3.8/traceback.py\"\
        , line 336, in extract\nMemoryError\n"


